<?xml version="1.0" encoding="UTF-8"?>
<testsuite errors="0" failures="2" file="scan_utils_tests.py" name="scan_utils_tests.TestScanUtils-20201130191128" skipped="0" tests="5" time="6.197" timestamp="2020-11-30T19:11:35">
	<testcase classname="scan_utils_tests.TestScanUtils" name="test_scan_many_ports_all_closed" time="1.554" timestamp="2020-11-30T19:11:30"/>
	<testcase classname="scan_utils_tests.TestScanUtils" name="test_scan_one_port_all_closed" time="0.805" timestamp="2020-11-30T19:11:34"/>
	<testcase classname="scan_utils_tests.TestScanUtils" name="test_scan_one_port_all_open" time="0.773" timestamp="2020-11-30T19:11:35"/>
	<testcase classname="scan_utils_tests.TestScanUtils" name="test_scan_many_ports_all_open" time="1.489" timestamp="2020-11-30T19:11:32">
		<failure message="{'3280': True, '3281': True, '3282': True, '32[89 chars]True} != {'3282': False, '3280': True, '3283': False, '[98 chars]alse}
  {'3280': True,
-  '3281': True,
?          ^^^

+  '3281': False,
?          ^^^^

-  '3282': True,
?          ^^^

+  '3282': False,
?          ^^^^

-  '3283': True,
?          ^^^

+  '3283': False,
?          ^^^^

-  '3284': True,
?          ^^^

+  '3284': False,
?          ^^^^

-  '3285': True,
?          ^^^

+  '3285': False,
?          ^^^^

-  '3286': True,
?          ^^^

+  '3286': False,
?          ^^^^

-  '3287': True,
?          ^^^

+  '3287': False,
?          ^^^^

-  '3288': True,
?          ^^^

+  '3288': False,
?          ^^^^

-  '3289': True}
?          ^^^

+  '3289': False}
?          ^^^^
" type="AssertionError">
<![CDATA[Traceback (most recent call last):
  File "/usr/lib/python3.6/unittest/case.py", line 59, in testPartExecutor
    yield
  File "/usr/lib/python3.6/unittest/case.py", line 605, in run
    testMethod()
  File "/home/student/Documents/cs3280project3/src/unittest/python/scan_utils_tests.py", line 75, in test_scan_many_ports_all_open
    self.assertEqual(test_dictionary, scanned_dictionary)
  File "/usr/lib/python3.6/unittest/case.py", line 829, in assertEqual
    assertion_func(first, second, msg=msg)
  File "/usr/lib/python3.6/unittest/case.py", line 1121, in assertDictEqual
    self.fail(self._formatMessage(msg, standardMsg))
  File "/usr/lib/python3.6/unittest/case.py", line 670, in fail
    raise self.failureException(msg)
AssertionError: {'3280': True, '3281': True, '3282': True, '32[89 chars]True} != {'3282': False, '3280': True, '3283': False, '[98 chars]alse}
  {'3280': True,
-  '3281': True,
?          ^^^

+  '3281': False,
?          ^^^^

-  '3282': True,
?          ^^^

+  '3282': False,
?          ^^^^

-  '3283': True,
?          ^^^

+  '3283': False,
?          ^^^^

-  '3284': True,
?          ^^^

+  '3284': False,
?          ^^^^

-  '3285': True,
?          ^^^

+  '3285': False,
?          ^^^^

-  '3286': True,
?          ^^^

+  '3286': False,
?          ^^^^

-  '3287': True,
?          ^^^

+  '3287': False,
?          ^^^^

-  '3288': True,
?          ^^^

+  '3288': False,
?          ^^^^

-  '3289': True}
?          ^^^

+  '3289': False}
?          ^^^^

]]>		</failure>
	</testcase>
	<testcase classname="scan_utils_tests.TestScanUtils" name="test_scan_many_ports_some_open" time="1.576" timestamp="2020-11-30T19:11:34">
		<failure message="{'3280': True, '3281': False, '3282': False, '[96 chars]True} != {'3282': False, '3280': False, '3285': False, [98 chars]alse}
- {'3280': True,
?          ^^^

+ {'3280': False,
?          ^^^^

   '3281': False,
   '3282': False,
   '3283': False,
   '3284': False,
-  '3285': True,
?          ^^^

+  '3285': False,
?          ^^^^

   '3286': False,
   '3287': False,
   '3288': False,
   '3289': True}" type="AssertionError">
<![CDATA[Traceback (most recent call last):
  File "/usr/lib/python3.6/unittest/case.py", line 59, in testPartExecutor
    yield
  File "/usr/lib/python3.6/unittest/case.py", line 605, in run
    testMethod()
  File "/home/student/Documents/cs3280project3/src/unittest/python/scan_utils_tests.py", line 87, in test_scan_many_ports_some_open
    self.assertEqual(test_dictionary, scanned_dictionary)
  File "/usr/lib/python3.6/unittest/case.py", line 829, in assertEqual
    assertion_func(first, second, msg=msg)
  File "/usr/lib/python3.6/unittest/case.py", line 1121, in assertDictEqual
    self.fail(self._formatMessage(msg, standardMsg))
  File "/usr/lib/python3.6/unittest/case.py", line 670, in fail
    raise self.failureException(msg)
AssertionError: {'3280': True, '3281': False, '3282': False, '[96 chars]True} != {'3282': False, '3280': False, '3285': False, [98 chars]alse}
- {'3280': True,
?          ^^^

+ {'3280': False,
?          ^^^^

   '3281': False,
   '3282': False,
   '3283': False,
   '3284': False,
-  '3285': True,
?          ^^^

+  '3285': False,
?          ^^^^

   '3286': False,
   '3287': False,
   '3288': False,
   '3289': True}
]]>		</failure>
	</testcase>
</testsuite>
